[2024-05-01T18:41:34.220+0000] {local_task_job_runner.py:120} INFO - ::group::Pre task execution logs
[2024-05-01T18:41:34.248+0000] {taskinstance.py:2073} INFO - Dependencies all met for dep_context=non-requeueable deps ti=<TaskInstance: weather_data_pipeline.fetch_and_display_data manual__2024-05-01T17:58:25.196953+00:00 [queued]>
[2024-05-01T18:41:34.262+0000] {taskinstance.py:2073} INFO - Dependencies all met for dep_context=requeueable deps ti=<TaskInstance: weather_data_pipeline.fetch_and_display_data manual__2024-05-01T17:58:25.196953+00:00 [queued]>
[2024-05-01T18:41:34.263+0000] {taskinstance.py:2303} INFO - Starting attempt 1 of 6
[2024-05-01T18:41:34.282+0000] {taskinstance.py:2327} INFO - Executing <Task(PythonOperator): fetch_and_display_data> on 2024-05-01 17:58:25.196953+00:00
[2024-05-01T18:41:34.290+0000] {warnings.py:110} WARNING - /home/***/.local/lib/python3.12/site-packages/***/task/task_runner/standard_task_runner.py:61: DeprecationWarning: This process (pid=945) is multi-threaded, use of fork() may lead to deadlocks in the child.
  pid = os.fork()

[2024-05-01T18:41:34.292+0000] {standard_task_runner.py:63} INFO - Started process 954 to run task
[2024-05-01T18:41:34.292+0000] {standard_task_runner.py:90} INFO - Running: ['***', 'tasks', 'run', 'weather_data_pipeline', 'fetch_and_display_data', 'manual__2024-05-01T17:58:25.196953+00:00', '--job-id', '11', '--raw', '--subdir', 'DAGS_FOLDER/demo.py', '--cfg-path', '/tmp/tmp19sxwepg']
[2024-05-01T18:41:34.293+0000] {standard_task_runner.py:91} INFO - Job 11: Subtask fetch_and_display_data
[2024-05-01T18:41:34.342+0000] {task_command.py:426} INFO - Running <TaskInstance: weather_data_pipeline.fetch_and_display_data manual__2024-05-01T17:58:25.196953+00:00 [running]> on host a747c391e266
[2024-05-01T18:41:34.437+0000] {taskinstance.py:2644} INFO - Exporting env vars: AIRFLOW_CTX_DAG_OWNER='***' AIRFLOW_CTX_DAG_ID='weather_data_pipeline' AIRFLOW_CTX_TASK_ID='fetch_and_display_data' AIRFLOW_CTX_EXECUTION_DATE='2024-05-01T17:58:25.196953+00:00' AIRFLOW_CTX_TRY_NUMBER='1' AIRFLOW_CTX_DAG_RUN_ID='manual__2024-05-01T17:58:25.196953+00:00'
[2024-05-01T18:41:34.439+0000] {taskinstance.py:430} INFO - ::endgroup::
[2024-05-01T18:41:34.480+0000] {taskinstance.py:441} INFO - ::group::Post task execution logs
[2024-05-01T18:41:34.481+0000] {taskinstance.py:2890} ERROR - Task failed with exception
Traceback (most recent call last):
  File "/home/airflow/.local/lib/python3.12/site-packages/sqlalchemy/engine/base.py", line 1910, in _execute_context
    self.dialect.do_execute(
  File "/home/airflow/.local/lib/python3.12/site-packages/sqlalchemy/engine/default.py", line 736, in do_execute
    cursor.execute(statement, parameters)
psycopg2.errors.UndefinedTable: relation "weather" does not exist
LINE 1: SELECT * FROM Weather
                      ^


The above exception was the direct cause of the following exception:

Traceback (most recent call last):
  File "/home/airflow/.local/lib/python3.12/site-packages/airflow/models/taskinstance.py", line 465, in _execute_task
    result = _execute_callable(context=context, **execute_callable_kwargs)
             ^^^^^^^^^^^^^^^^^^^^^^^^^^^^^^^^^^^^^^^^^^^^^^^^^^^^^^^^^^^^^
  File "/home/airflow/.local/lib/python3.12/site-packages/airflow/models/taskinstance.py", line 432, in _execute_callable
    return execute_callable(context=context, **execute_callable_kwargs)
           ^^^^^^^^^^^^^^^^^^^^^^^^^^^^^^^^^^^^^^^^^^^^^^^^^^^^^^^^^^^^
  File "/home/airflow/.local/lib/python3.12/site-packages/airflow/models/baseoperator.py", line 400, in wrapper
    return func(self, *args, **kwargs)
           ^^^^^^^^^^^^^^^^^^^^^^^^^^^
  File "/home/airflow/.local/lib/python3.12/site-packages/airflow/operators/python.py", line 235, in execute
    return_value = self.execute_callable()
                   ^^^^^^^^^^^^^^^^^^^^^^^
  File "/home/airflow/.local/lib/python3.12/site-packages/airflow/operators/python.py", line 252, in execute_callable
    return self.python_callable(*self.op_args, **self.op_kwargs)
           ^^^^^^^^^^^^^^^^^^^^^^^^^^^^^^^^^^^^^^^^^^^^^^^^^^^^^
  File "/opt/airflow/dags/demo.py", line 55, in fetch_and_display_data
    result = conn.execute(query)
             ^^^^^^^^^^^^^^^^^^^
  File "/home/airflow/.local/lib/python3.12/site-packages/sqlalchemy/engine/base.py", line 1370, in execute
    return self._exec_driver_sql(
           ^^^^^^^^^^^^^^^^^^^^^^
  File "/home/airflow/.local/lib/python3.12/site-packages/sqlalchemy/engine/base.py", line 1674, in _exec_driver_sql
    ret = self._execute_context(
          ^^^^^^^^^^^^^^^^^^^^^^
  File "/home/airflow/.local/lib/python3.12/site-packages/sqlalchemy/engine/base.py", line 1953, in _execute_context
    self._handle_dbapi_exception(
  File "/home/airflow/.local/lib/python3.12/site-packages/sqlalchemy/engine/base.py", line 2134, in _handle_dbapi_exception
    util.raise_(
  File "/home/airflow/.local/lib/python3.12/site-packages/sqlalchemy/util/compat.py", line 211, in raise_
    raise exception
  File "/home/airflow/.local/lib/python3.12/site-packages/sqlalchemy/engine/base.py", line 1910, in _execute_context
    self.dialect.do_execute(
  File "/home/airflow/.local/lib/python3.12/site-packages/sqlalchemy/engine/default.py", line 736, in do_execute
    cursor.execute(statement, parameters)
sqlalchemy.exc.ProgrammingError: (psycopg2.errors.UndefinedTable) relation "weather" does not exist
LINE 1: SELECT * FROM Weather
                      ^

[SQL: SELECT * FROM Weather]
(Background on this error at: https://sqlalche.me/e/14/f405)
[2024-05-01T18:41:34.498+0000] {taskinstance.py:1205} INFO - Marking task as UP_FOR_RETRY. dag_id=weather_data_pipeline, task_id=fetch_and_display_data, execution_date=20240501T175825, start_date=20240501T184134, end_date=20240501T184134
[2024-05-01T18:41:34.514+0000] {standard_task_runner.py:110} ERROR - Failed to execute job 11 for task fetch_and_display_data ((psycopg2.errors.UndefinedTable) relation "weather" does not exist
LINE 1: SELECT * FROM Weather
                      ^

[SQL: SELECT * FROM Weather]
(Background on this error at: https://sqlalche.me/e/14/f405); 954)
[2024-05-01T18:41:34.547+0000] {local_task_job_runner.py:240} INFO - Task exited with return code 1
[2024-05-01T18:41:34.572+0000] {taskinstance.py:3482} INFO - 0 downstream tasks scheduled from follow-on schedule check
[2024-05-01T18:41:34.576+0000] {local_task_job_runner.py:222} INFO - ::endgroup::
