[2024-05-01T17:58:30.773+0000] {local_task_job_runner.py:120} INFO - ::group::Pre task execution logs
[2024-05-01T17:58:30.799+0000] {taskinstance.py:2073} INFO - Dependencies all met for dep_context=non-requeueable deps ti=<TaskInstance: weather_data_pipeline.read_and_clean_csv manual__2024-05-01T17:58:25.196953+00:00 [queued]>
[2024-05-01T17:58:30.809+0000] {taskinstance.py:2073} INFO - Dependencies all met for dep_context=requeueable deps ti=<TaskInstance: weather_data_pipeline.read_and_clean_csv manual__2024-05-01T17:58:25.196953+00:00 [queued]>
[2024-05-01T17:58:30.810+0000] {taskinstance.py:2303} INFO - Starting attempt 1 of 6
[2024-05-01T17:58:30.827+0000] {taskinstance.py:2327} INFO - Executing <Task(PythonOperator): read_and_clean_csv> on 2024-05-01 17:58:25.196953+00:00
[2024-05-01T17:58:30.834+0000] {warnings.py:110} WARNING - /home/***/.local/lib/python3.12/site-packages/***/task/task_runner/standard_task_runner.py:61: DeprecationWarning: This process (pid=397) is multi-threaded, use of fork() may lead to deadlocks in the child.
  pid = os.fork()

[2024-05-01T17:58:30.837+0000] {standard_task_runner.py:63} INFO - Started process 399 to run task
[2024-05-01T17:58:30.837+0000] {standard_task_runner.py:90} INFO - Running: ['***', 'tasks', 'run', 'weather_data_pipeline', 'read_and_clean_csv', 'manual__2024-05-01T17:58:25.196953+00:00', '--job-id', '6', '--raw', '--subdir', 'DAGS_FOLDER/demo.py', '--cfg-path', '/tmp/tmpeaktgf9z']
[2024-05-01T17:58:30.838+0000] {standard_task_runner.py:91} INFO - Job 6: Subtask read_and_clean_csv
[2024-05-01T17:58:30.893+0000] {task_command.py:426} INFO - Running <TaskInstance: weather_data_pipeline.read_and_clean_csv manual__2024-05-01T17:58:25.196953+00:00 [running]> on host a747c391e266
[2024-05-01T17:58:30.992+0000] {taskinstance.py:2644} INFO - Exporting env vars: AIRFLOW_CTX_DAG_OWNER='***' AIRFLOW_CTX_DAG_ID='weather_data_pipeline' AIRFLOW_CTX_TASK_ID='read_and_clean_csv' AIRFLOW_CTX_EXECUTION_DATE='2024-05-01T17:58:25.196953+00:00' AIRFLOW_CTX_TRY_NUMBER='1' AIRFLOW_CTX_DAG_RUN_ID='manual__2024-05-01T17:58:25.196953+00:00'
[2024-05-01T17:58:30.994+0000] {taskinstance.py:430} INFO - ::endgroup::
[2024-05-01T17:58:31.000+0000] {taskinstance.py:441} INFO - ::group::Post task execution logs
[2024-05-01T17:58:31.001+0000] {taskinstance.py:2890} ERROR - Task failed with exception
Traceback (most recent call last):
  File "/home/airflow/.local/lib/python3.12/site-packages/airflow/models/taskinstance.py", line 465, in _execute_task
    result = _execute_callable(context=context, **execute_callable_kwargs)
             ^^^^^^^^^^^^^^^^^^^^^^^^^^^^^^^^^^^^^^^^^^^^^^^^^^^^^^^^^^^^^
  File "/home/airflow/.local/lib/python3.12/site-packages/airflow/models/taskinstance.py", line 432, in _execute_callable
    return execute_callable(context=context, **execute_callable_kwargs)
           ^^^^^^^^^^^^^^^^^^^^^^^^^^^^^^^^^^^^^^^^^^^^^^^^^^^^^^^^^^^^
  File "/home/airflow/.local/lib/python3.12/site-packages/airflow/models/baseoperator.py", line 400, in wrapper
    return func(self, *args, **kwargs)
           ^^^^^^^^^^^^^^^^^^^^^^^^^^^
  File "/home/airflow/.local/lib/python3.12/site-packages/airflow/operators/python.py", line 235, in execute
    return_value = self.execute_callable()
                   ^^^^^^^^^^^^^^^^^^^^^^^
  File "/home/airflow/.local/lib/python3.12/site-packages/airflow/operators/python.py", line 252, in execute_callable
    return self.python_callable(*self.op_args, **self.op_kwargs)
           ^^^^^^^^^^^^^^^^^^^^^^^^^^^^^^^^^^^^^^^^^^^^^^^^^^^^^
  File "/opt/airflow/dags/demo.py", line 11, in read_and_clean_csv
    weather_df = pd.read_csv('/data/raw_weather_NPM.csv')
                 ^^^^^^^^^^^^^^^^^^^^^^^^^^^^^^^^^^^^^^^^
  File "/home/airflow/.local/lib/python3.12/site-packages/pandas/io/parsers/readers.py", line 948, in read_csv
    return _read(filepath_or_buffer, kwds)
           ^^^^^^^^^^^^^^^^^^^^^^^^^^^^^^^
  File "/home/airflow/.local/lib/python3.12/site-packages/pandas/io/parsers/readers.py", line 611, in _read
    parser = TextFileReader(filepath_or_buffer, **kwds)
             ^^^^^^^^^^^^^^^^^^^^^^^^^^^^^^^^^^^^^^^^^^
  File "/home/airflow/.local/lib/python3.12/site-packages/pandas/io/parsers/readers.py", line 1448, in __init__
    self._engine = self._make_engine(f, self.engine)
                   ^^^^^^^^^^^^^^^^^^^^^^^^^^^^^^^^^
  File "/home/airflow/.local/lib/python3.12/site-packages/pandas/io/parsers/readers.py", line 1705, in _make_engine
    self.handles = get_handle(
                   ^^^^^^^^^^^
  File "/home/airflow/.local/lib/python3.12/site-packages/pandas/io/common.py", line 863, in get_handle
    handle = open(
             ^^^^^
FileNotFoundError: [Errno 2] No such file or directory: '/data/raw_weather_NPM.csv'
[2024-05-01T17:58:31.016+0000] {taskinstance.py:1205} INFO - Marking task as UP_FOR_RETRY. dag_id=weather_data_pipeline, task_id=read_and_clean_csv, execution_date=20240501T175825, start_date=20240501T175830, end_date=20240501T175831
[2024-05-01T17:58:31.038+0000] {standard_task_runner.py:110} ERROR - Failed to execute job 6 for task read_and_clean_csv ([Errno 2] No such file or directory: '/data/raw_weather_NPM.csv'; 399)
[2024-05-01T17:58:31.051+0000] {local_task_job_runner.py:240} INFO - Task exited with return code 1
[2024-05-01T17:58:31.076+0000] {taskinstance.py:3482} INFO - 0 downstream tasks scheduled from follow-on schedule check
[2024-05-01T17:58:31.079+0000] {local_task_job_runner.py:222} INFO - ::endgroup::
